Workbook
Name Back_testing_LGD: Glossary!$B$7
Name Bank_s_assessment: Glossary!$B$8
Name Bank_s_comments: Glossary!$B$9
Name Coverage_in_internal_validation: Glossary!$B$10
Name Discriminatory_Power_LGD: Glossary!$B$11
Name Duration_of_the_recovery_process: Glossary!$B$12
Name Estimation_period: Glossary!$B$13
Name Expected_Loss: Glossary!$B$14
Name Exposure_at_Default: Glossary!$B$15
Name Exposure_Value: Glossary!$B$16
Name Facility_grade___pool: Glossary!$B$17
Name Generalised_AUC: Glossary!$B$18
Name Information_on_the_initial_sample: Glossary!$B$19
Name LGD_1.0a: '1.0'!$C$5
Name LGD_1.0b: '1.0'!$C$7
Name LGD_1.0c: '1.0'!$C$9
Name LGD_1.0d: '1.0'!$C$11
Name LGD_1.0e: '1.0'!$C$13
Name LGD_1.0f: '1.0'!$C$15
Name LGD_1.0g: '1.0'!$C$17
Name LGD_1.1a: '1.1'!$G$6:$I$9
Name LGD_1.1b: '1.1'!$E$14:$I$17
Name LGD_1.2a: '1.2'!$D$7:$E$12
Name LGD_2.0a: '2.0'!$E$8:$W$8
Name LGD_2.0b: '2.0'!$E$10:$E$21
Name LGD_2.0c: '2.0'!$G$10:$W$21
Name LGD_2.1a: '2.1'!$E$7:$AF$7
Name LGD_2.1b: '2.1'!$D$9:$E$28
Name LGD_2.1c: '2.1'!$G$9:$AF$28
Name LGD_3.0a: '3.0'!$D$7:$L$7
Name LGD_4.1a: '4.1'!$D$7:$E$7
Name LGD_4.2a: '4.2'!$D$9:$M$28
Name LGD_4.2b: '4.2'!$E$33
Name LGD_4.3a: '4.3'!$D$7:$E$11
Name LGD_4.3b: '4.3'!$D$15
Name LGD_Distribution: Glossary!$B$20
Name Loan_to_Value: Glossary!#REF!
Name Missing_Values_LGD: Glossary!$B$21
Name Model__ID: Glossary!$B$22
Name Modelling_approach: Glossary!$B$23
Name Number_facilities__backtesting: Glossary!$B$25
Name number_facilities_default: Glossary!$B$26
Name Number_of_facilities__application_portfolio: Glossary!$B$24
Name Number_of_Facility_Grades_or_Pools__K: Glossary!$B$27
Name Original_exposure: Glossary!$B$28
Name Portfolio: Glossary!$B$29
Name Relevant_observation_period: Glossary!$B$30
Name Risk_Weighted_Exposure_Amount: Glossary!$B$31
Name Time_in_default: Glossary!$B$32
Name Var_gAUC_init: Glossary!$B$33

Sheet Index
B2: VALIDATION REPORTING CREDIT RISK: INDIVIDUAL LGD MODEL
B4: TEMPLATES | G4: DQ check
B5: Number | C5: Code | D5: Name | E5: Reporting instructions | G5: Assessment
B6: 1 | C6: LGD 1.0 | D6: GENERAL INFORMATION - MODEL | E6: Section 2.4.1 | G6: =IF(COUNTIF('1.0'!C20:C22,"NOT OK")=0,"OK","NOT OK") -> NOT OK
B7: 1.1 | C7: LGD 1.1 | D7: VALIDATION INFORMATION - MODEL | E7: Section 2.4.2 | G7: =IF(COUNTIF('1.1'!K6:K17,"NOT OK")=0,"OK","NOT OK") -> NOT OK
B8: 1.2 | C8: LGD 1.2 | D8: PORTFOLIO INFORMATION | E8: Section 2.4.3 | G8: =IF(COUNTIF('1.2'!H7:H12,"NOT OK")=0,IF(COUNTIF('1.2'!H7:H12,"WARNING")=0,"OK","WARNING"),"NOT OK") -> NOT OK
B9: 2.0 | C9: LGD 2.0 | D9: BACK-TESTING (> 20 FACILITY GRADES OR POOLS, CONTINUOUS MODEL) | E9: Section 2.6.2 | G9: =IF('1.2'!E11="More than 20 facility grades or pools (including continuous LGD models)", IF(COUNTIF('2.0'!Y8:Y21,"NOT OK")=0,IF(COUNTIF('2.0'!Y8:Y21,"WARNING")=0,"OK","WARNING"),"NOT OK"), "NOT ASSESSED") -> NOT ASSESSED
B10: 2.1 | C10: LGD 2.1 | D10: BACK-TESTING (≤ 20 FACILITY GRADES OR POOLS) | E10: Section 2.6.2 | G10: =IF('1.2'!E11="Less than or equal to 20 facility grades or pools",IF(COUNTIF('2.1'!AH7:AH28,"NOT OK")=0,IF(COUNTIF('2.1'!AH7:AH28,"WARNING")=0,"OK","WARNING"),"NOT OK"),"NOT ASSESSED") -> NOT ASSESSED
B11: 3.0 | C11: LGD 3.0 | D11: DISCRIMINATORY POWER | E11: Section 2.6.3.1 | G11: =IF(COUNTIF('3.0'!E9:L9,"NOT OK")=0,IF(COUNTIF('3.0'!E9:L9,"WARNING")=0,"OK","WARNING"),"NOT OK") -> NOT OK
B12: 4.1 | C12: LGD 4.1 | D12: QUALITATIVE VALIDATION TOOLS - MISSING VALUES | E12: Section 2.6.4.1 | G12: =IF(COUNTIF('4.1'!C10:C10,"NOT OK")=0,IF(COUNTIF('4.1'!C10:C10,"WARNING")=0,"OK","WARNING"),"NOT OK") -> NOT OK
B13: 4.2 | C13: LGD 4.2 | D13: QUALITATIVE VALIDATION TOOLS - LGD DISTRIBUTION | E13: Section 2.6.4.2 | G13: =IF(COUNTIF('4.2'!O9:O37,"NOT OK")=0,IF(COUNTIF('4.2'!O9:O37,"WARNING")=0,"OK","WARNING"),"NOT OK") -> OK
B14: 4.3 | C14: LGD 4.3 | D14: QUALITATIVE VALIDATION TOOLS - TIME IN DEFAULT | E14: Section 2.6.4.3 | G14: =IF(COUNTIF('4.3'!H7:H15,"NOT OK")=0,IF(COUNTIF('4.3'!H7:H15,"WARNING")=0,"OK","WARNING"),"NOT OK") -> NOT OK

Sheet 1.0
B2: LGD 1.0 - VALIDATION REPORTING CREDIT RISK: INDIVIDUAL LGD MODEL
E3: Template version: | F3: 1.31
B5: Country: (two letter ISO code)
B7: Bank LEI code: (mandatory, key identification field)
B9: Bank: (name of institution)
B11: Model ID:
B13: Internal model name: (as used in validation report)
B15: Start of relevant observation period:
B17: End of relevant observation period:
B19: DQ check
B20: Complete | C20: =IF(COUNTA(C5,C7,C9,C11,C13,C15,C17)=7,"OK","NOT OK") -> NOT OK | D20: =IF(COUNTA(C5,C7,C9,C11,C13,C15,C17)=7,"","Some of the requested information above is missing.") -> Some of the requested information above is missing.
B21: Observation period | C21: =IF(NOT(AND('1.0'!C36,C35,C38)),"NOT OK",IF(NOT(C37),"WARNING","OK")) -> NOT OK | D21: =IF(NOT(C35),D35,IF(NOT(C36),D36,IF(NOT(C38),D38,IF(NOT(C37),D37,"")))) -> End date < Start date
B22: Filename | C22: =IF(COUNTIF('1.0'!C24, C7&"_LGD_"&C11&"_"&TEXT(DAY(C17),"00")&TEXT(MONTH(C17),"00")&TEXT(YEAR(C17),"0000")&"_?.xlsx"), "OK", "NOT OK") -> NOT OK | D22: =IF(C22="OK","","Filename does not match naming convention.") -> Filename does not match naming convention.
B24: Current filename | C24: =REPLACE(LEFT(CELL("filename",A1),FIND("]",CELL("filename",A1))-1),1,FIND("[",CELL("filename",A1)),"") -> LEICode_LGD_ModelID_EndOfObservationPeriod_versionNumber.xlsx
B25: Suggested filename | C25: =C7&"_LGD_"&C11&"_"&IF(DAY(C17)<10,"0","")&DAY(C17)&IF(MONTH(C17)<10,"0","")&MONTH(C17)&YEAR(C17)&"_[#].xlsx" -> _LGD__00011900_[#].xlsx
B28: Today | C28: =TODAY() -> 45996
B29: Body suggested | C29: =C7&"_LGD_"&C11&"_"&IF(DAY(C17)<10,"0","")&DAY(C17)&IF(MONTH(C17)<10,"0","")&MONTH(C17)&YEAR(C17)&"_" -> _LGD__00011900_
B30: Body actual | C30: =LEFT(C24,C31) -> LEICode_LGD_Mod
B31: Len suggested | C31: =LEN(C29) -> 15
B32: Len actual | C32: =LEN(C24)-6 -> 55 | D32: Note: 5 chars for suffix plus "dot", one char for number
B34: Obs Period Validation: | C34: Result | D34: Text if FALSE
B35: End date > start date? | C35: =C17>C15 -> FALSE | D35: End date < Start date
B36: One year length | C36: =OR(DAYS360(C15,C17)=360,DAYS360(C15,C17)=359, AND(MONTH(C15)=2,MONTH(C17)=2,DAYS360(C15,C17)=358)) -> FALSE | D36: Observation period should be one year
B37: Younger than two years | C37: =C17>=DATE(YEAR(TODAY())-2,MONTH(TODAY()),DAY(TODAY())) -> FALSE | D37: Sample period seems to be outdated
B38: End date not in future | C38: =C17<=TODAY() -> TRUE | D38: Observation period ends in future

Sheet 1.1
B2: LGD 1.1 - VALIDATION INFORMATION - MODEL
C4: Question | G4: Answer | I4: Institution's comments | K4: DQ check
G5: 010 | I5: 020 | K5: Assessment | L5: Comment
B6: 100 | C6: What is the overall assessment of the reported model by the internal validation function? | K6: =IF(OR(G6={"Adequate with no deficiencies","Adequate with minor deficiencies","Major deficiencies identified","Severe deficiencies identified"}),"OK","NOT OK") -> NOT OK | L6: =IF(G6="", "Row incomplete", IF(K6="NOT OK","Improper value given","")) -> Row incomplete
B7: 200 | C7: Was a material model change implemented for the model during the relevant observation period? | K7: =IF(G7="","NOT OK", IF(OR(G7="Yes",G7="No"),"OK","NOT OK")) -> NOT OK | L7: =IF(K7="OK","",IF(G7="","Row incomplete","Invalid entry")) -> Row incomplete
B8: 300 | C8: Did the definition of facility grades/pools change between the beginning and end of the observation period? | K8: =IF(L8="", "OK", "NOT OK") -> NOT OK | L8: =IF(G8="","Row incomplete",IF(NOT(OR(AND('1.2'!D9 = '1.2'!E9,'1.1'!G8 = "No"),'1.1'!G8 = "Yes")),"Answer not consistent with the number of facility grades/pools given in sheet 1.2 ","")) -> Row incomplete
B9: 400 | C9: Does the model design allow a separation of the downturn component from the estimated LGD? | K9: =IF(G9="","NOT OK", IF(OR(G9="Yes",G9="No"),"OK","NOT OK")) -> NOT OK | L9: =IF(K9="OK","",IF(G9="","Row incomplete","Invalid entry")) -> Row incomplete
C11: Area of investigation | D11: Tables | E11: Link to bank's internal validation report | I11: Institution's comments | K11: DQ check
E12: Name of the validation report document | F12: Section number | G12: Page | H12: Coverage in internal validation | I12: Institution's comments on the reported figures and results (max. 1,000 characters each)
E13: 030 | F13: 040 | G13: 050 | H13: 060 | I13: 070 | K13: Assessment | L13: Comment | O13: Not too little information | P13: Not too much information
B14: 510 | C14: Portfolio information | D14: LGD 1.2 | K14: =IF('1.1'!P14,"OK",IF(O14,"OK","NOT OK")) -> NOT OK | L14: =IF(ISBLANK('1.1'!H14), "Row incomplete - please fill at least column 060", IF(K14="OK","",IF(AND(H14 <> "NOT ASSESSED",NOT(O14)),"Missing references to validation report",IF(AND(O14,NOT(P14)),"","References to validation report given although area is not assessed")))) -> Row incomplete - please fill at least column 060 | O14: =AND('1.1'!H14<>"NOT ASSESSED",COUNTA(E14:H14)=4) -> FALSE | P14: =AND('1.1'!H14="NOT ASSESSED",COUNTA(E14:G14)=0) -> FALSE
B15: 520 | C15: Predictive ability | D15: LGD 2.0, LGD 2.1 | K15: =IF('1.1'!P15,"OK",IF(O15,"OK","NOT OK")) -> NOT OK | L15: =IF(ISBLANK('1.1'!H15), "Row incomplete - please fill at least column 060", IF(K15="OK","",IF(AND(H15 <> "NOT ASSESSED",NOT(O15)),"Missing references to validation report",IF(AND(O15,NOT(P15)),"","References to validation report given although area is not assessed")))) -> Row incomplete - please fill at least column 060 | O15: =AND('1.1'!H15<>"NOT ASSESSED",COUNTA(E15:H15)=4) -> FALSE | P15: =AND('1.1'!H15="NOT ASSESSED",COUNTA(E15:G15)=0) -> FALSE
B16: 530 | C16: Discriminatory power | D16: LGD 3.0 | K16: =IF('1.1'!P16,"OK",IF(O16,"OK","NOT OK")) -> NOT OK | L16: =IF(ISBLANK('1.1'!H16), "Row incomplete - please fill at least column 060", IF(K16="OK","",IF(AND(H16 <> "NOT ASSESSED",NOT(O16)),"Missing references to validation report",IF(AND(O16,NOT(P16)),"","References to validation report given although area is not assessed")))) -> Row incomplete - please fill at least column 060 | O16: =AND('1.1'!H16<>"NOT ASSESSED",COUNTA(E16:H16)=4) -> FALSE | P16: =AND('1.1'!H16="NOT ASSESSED",COUNTA(E16:G16)=0) -> FALSE
B17: 540 | C17: Qualitative validation tools | D17: LGD 4.1, LGD 4.2, LGD 4.3 | K17: =IF('1.1'!P17,"OK",IF(O17,"OK","NOT OK")) -> NOT OK | L17: =IF(ISBLANK('1.1'!H17), "Row incomplete - please fill at least column 060", IF(K17="OK","",IF(AND(H17 <> "NOT ASSESSED",NOT(O17)),"Missing references to validation report",IF(AND(O17,NOT(P17)),"","References to validation report given although area is not assessed")))) -> Row incomplete - please fill at least column 060 | O17: =AND('1.1'!H17<>"NOT ASSESSED",COUNTA(E17:H17)=4) -> FALSE | P17: =AND('1.1'!H17="NOT ASSESSED",COUNTA(E17:G17)=0) -> FALSE

Sheet 1.2
B2: LGD 1.2 - PORTFOLIO INFORMATION
B4: Application portfolio of the LGD model (performing)
C5: Measure | D5: Beginning of the observation period | E5: End of the observation period | F5: Change | H5: DQ check
D6: 010 | E6: 020 | F6: 030 | H6: Assessment | I6: Comment
B7: 110 | C7: RWEA | F7: =IF(AND(E7<>"",D7<>""),IF(D7<>0,(E7-D7)/'1.2'!D7,""),"") | H7: =IF(COUNTA(D7:E7)<>2,"NOT OK",IF('1.2'!D7=E7,"WARNING","OK")) -> NOT OK | I7: =IF(COUNTA(D7:E7)<>2,"Row incomplete",IF(D7=E7,"Same information for beginning and end of observation period","")) -> Row incomplete
B8: 120 | C8: EAD | F8: =IF(AND(E8<>"",D8<>""),IF(D8<>0,(E8-D8)/'1.2'!D8,""),"") | H8: =IF(COUNTA(D8:E8)<>2,"NOT OK",IF('1.2'!D8=E8,"WARNING","OK")) -> NOT OK | I8: =IF(COUNTA(D8:E8)<>2,"Row incomplete",IF(D8=E8,"Same information for beginning and end of observation period","")) -> Row incomplete
B9: 130 | C9: Number of facility grades or pools | F9: =IF(AND(E9<>"",D9<>""),IF(D9<>0,(E9-D9)/'1.2'!D9,""),"") | H9: =IF(I9="Missing values only allowed for continuous models.","WARNING",IF(I9="", "OK","NOT OK")) -> NOT OK | I9: =IF(AND(COUNTA(E9)=0,E11<>"More than 20 facility grades or pools (including continuous LGD models)"),"Row incomplete", IF(AND(COUNTA(D9)=0,D11<>"More than 20 facility grades or pools (including continuous LGD models)"),"Row incomplete", IF(AND(COUNTA(E9)=0,E11="More than 20 facility grades or pools (including continuous LGD models)"),"Missing values only allowed for continuous models.", IF(AND(COUNTA(D9)=0,D11="More than 20 facility grades or pools (including continuous LGD models)"),"Missing values only allowed for continuous models.", IF(AND(D9<>E9,'1.1'!G8="No"),"Different number of facility grades",""))))) -> Row incomplete
B10: 150 | C10: Number of facilities (application portfolio) | F10: =IF(AND(E10<>"",D10<>""),IF(D10<>0,(E10-D10)/'1.2'!D10,""),"") | H10: =IF(COUNTA(D10:E10)<>2,"NOT OK",IF('1.2'!D10=E10,"WARNING","OK")) -> NOT OK | I10: =IF(COUNTA(D10:E10)<>2,"Row incomplete",IF(D10=E10,"Same information for beginning and end of observation period","")) -> Row incomplete
B11: 160 | C11: Modelling approach | H11: =IF(OR(COUNTA(D11:E11)<>2, I11="Modelling approach not in line with reported number of facility grades or pools in row 130 (which is less or equal 20).", I11="Modelling approach not in line with reported number of facility grades or pools in row 130 (which is greater than 20)."),"NOT OK", IF('1.2'!D11<>E11,"WARNING","OK")) -> NOT OK | I11: =IFERROR(IF(COUNTA(D11:E11)<>2,"Row incomplete", IF(OR(AND(D11="More than 20 facility grades or pools (including continuous LGD models)",COUNTA(D9),D9<=20), AND(E11="More than 20 facility grades or pools (including continuous LGD models)",COUNTA(E9),E9<=20)), "Modelling approach not in line with reported number of facility grades or pools in row 130 (which is less or equal 20).", IF(OR(AND(D11="Less than or equal to 20 facility grades or pools",COUNTA(D9),D9>20), AND(E11="Less than or equal to 20 facility grades or pools",COUNTA(E9),E9>20)), "Modelling approach not in line with reported number of facility grades or pools in row 130 (which is greater than 20).", IF(D11<>E11,"Different modelling approaches", "")))),"") -> Row incomplete
B12: 170 | C12: Estimation period | H12: =IF(COUNTA(D12:E12)<>2,"NOT OK",IF('1.2'!D12<>E12,"WARNING","OK")) -> NOT OK | I12: =IF(COUNTA(D12:E12)<>2,"Row incomplete",IF(D12<>E12,"Different estimation period","")) -> Row incomplete
D15: More than 20 facility grades or pools (including continuous LGD models) | F15: Estimates calculated at the beginning of the year in which the default occurred
D16: Less than or equal to 20 facility grades or pools | F16: Estimates calculated 12 months before the individual default

Sheet 2.0
B2: LGD 2.0 - BACK-TESTING LGD (MORE THAN 20 FACILITY GRADES OR POOLS - INCLUDING CONTINUOUS LGD MODELS)
D4: Estimated LGD | E4: Number of facilities (back-testing) | F4: Number-weighted average of estimated LGD without downturn component (if available) | G4: Number-weighted average of estimated LGD (LGD^E) | H4: Number-weighted average of realised LGD (LGD^R) | I4: Observed frequencies realised LGD (LGD^R) | U4: T-test
E5: N | F5: Number Weighted Average of Estimated LGD (LGD^E) | G5: Number Weighted Average of Estimated LGD (LGD^E) | U5: Variance (s^2_LGD) | V5: Test statistic (T) | W5: P-value (1-S_N-1(T)) | Y5: DQ check | AR5: Discriminatory power
I6: [0%,5%) | J6: [5%,10%) | K6: [10%,20%) | L6: [20%,30%) | M6: [30%,40%) | N6: [40%,50%) | O6: [50%,60%) | P6: [60%,70%) | Q6: [70%,80%) | R6: [80%,90%) | S6: [90%,100%) | T6: >=100% | Y6: Assessment | Z6: Comment | AC6: LGD realisation bounds | AF6: LGD variance bounds | AI6: P-value t-test | AJ6: P-value t-test
D7: 010 | E7: 020 | F7: 030 | G7: 040 | H7: 050 | I7: 060 | J7: 070 | K7: 080 | L7: 090 | M7: 100 | N7: 110 | O7: 120 | P7: 130 | Q7: 140 | R7: 150 | S7: 160 | T7: 170 | U7: 180 | V7: 190 | W7: 200 | AA7: Row complete | AB7: Row sum | AC7: LGD^R_low | AD7: LGD^R_up | AE7: LGD_R bounds | AF7: VAR_low | AG7: VAR_up | AH7: VAR bounds | AK7: LGD_LB | AL7: LGD_UB | AM7: LGD^E_prox | AR7: ECB calculation | AV7: ECB calculation for Aij - Dij
B8: 100 | C8: Portfolio | D8: Portfolio | Y8: =IF(COUNTA(E8:W8)=0,"", IF(F8>G8, "NOT OK", IF(OR('2.0'!AA8="NOT OK",AB8="NOT OK",AJ8="NOT OK",ISNUMBER(SEARCH("is not a weighted average of the segment values",Z8))),"NOT OK",IF(AND(OR(AE8="WARNING",AH8="WARNING"),E8>0),"WARNING","OK")))) | Z8: =IF(COUNTA(E8:W8)=0,"",IF('2.0'!AA8="NOT OK","Row incomplete. Check if zeros values are missing in the row.",IF(AB8="NOT OK","The number of facilities in buckets does not sum up to the total number.",IF(AJ8="NOT OK","The p-value of t-Test differs from ECB calculation.",IF(ABS(SUMPRODUCT(E10:E21,G10:G21)/E8-G8)>0.00001,"Cell G8 is not a weighted average of the segment values.[ECB calculation: "&ROUND(SUMPRODUCT(E10:E21,G10:G21)/E8,6)&"]",IF(ABS(SUMPRODUCT(E10:E21,H10:H21)/E8-H8)>0.00001,"Cell H8 is not a weighted average of the segment values.[ECB calculation: "&ROUND(SUMPRODUCT(E10:E21,H10:H21)/E8,6)&"]",IF(AE8="WARNING","The average LGD^R seems implausible with the given LGD realisation.",IF(AH8="WARNING","The variance of the LGD seems implausible with the given realisation.",IF(SUM(I10:I21)<>I8,"Cell I8 is not the sum of the segment values.[ECB calculation: "&SUM(I10:I21)&"]",IF(SUM(J10:J21)<>J8,"Cell J8 is not the sum of the segment values.[ECB calculation: "&SUM(J10:J21)&"]",IF(SUM(K10:K21)<>K8,"Cell K8 is not the sum of the segment values.[ECB calculation: "&SUM(K10:K21)&"]",IF(SUM(L10:L21)<>L8,"Cell L8 is not the sum of the segment values.[ECB calculation: "&SUM(L10:L21)&"]",IF(SUM(M10:M21)<>M8,"Cell M8 is not the sum of the segment values.[ECB calculation: "&SUM(M10:M21)&"]",IF(SUM(N10:N21)<>N8,"Cell N8 is not the sum of the segment values.[ECB calculation: "&SUM(N10:N21)&"]",IF(SUM(O10:O21)<>O8,"Cell O8 is not the sum of the segment values.[ECB calculation: "&SUM(O10:O21)&"]",IF(SUM(P10:P21)<>P8,"Cell P8 is not the sum of the segment values.[ECB calculation: "&SUM(P10:P21)&"]",IF(SUM(Q10:Q21)<>Q8,"Cell Q8 is not the sum of the segment values.[ECB calculation: "&SUM(Q10:Q21)&"]",IF(SUM(R10:R21)<>R8,"Cell R8 is not the sum of the segment values.[ECB calculation: "&SUM(R10:R21)&"]",IF(SUM(S10:S21)<>S8,"Cell S8 is not the sum of the segment values.[ECB calculation: "&SUM(S10:S21)&"]",IF(SUM(T10:T21)<>T8,"Cell T8 is not the sum of the segment values.[ECB calculation: "&SUM(T10:T21)&"]",IF(F8>G8,"Cell F8 should be smaller or equal to Cell G8.",""))))))))))))))))))))) | AA8: =IF(OR(E8=0,COUNTA(E8:W8)=0),"",IF(COUNTA(E8,G8:W8)>=18,"OK",IF('2.0'!E8=1,IF(COUNTA(E8,G8:W8)=15,"OK","NOT OK"),"NOT OK"))) | AB8: =IF(COUNTA(E8:W8)=0,"",IF(AND(E8=SUM(I8:T8),'2.0'!E8=SUM(E10:E21)),"OK","NOT OK")) | AC8: {=IFERROR(SUM(I8:T8*TRANSPOSE($AK$10:$AK$21))/SUM(I8:T8),"")} | AD8: {=IFERROR(SUM(I8:T8*TRANSPOSE($AL$10:$AL$21))/SUM(I8:T8),"")} | AE8: =IF(COUNTA(E8:W8)=0,"",IFERROR(IF(AND('2.0'!H8>=AC8,H8<=AD8),"OK","WARNING"),"")) | AF8: =IF(COUNTA(E8:W8)=0,"",IFERROR('2.0'!AP30,"")) | AG8: =IF(COUNTA(E8:W8)=0,"",IFERROR('2.0'!AO30,"")) | AH8: =IF(COUNTA(E8:W8)=0,"",IFERROR(IF(AND('2.0'!U8>=AF8,U8<=AG8),"OK","WARNING"),"")) | AI8: =IFERROR(IF(COUNTA(E8:W8)=0,"",1-_xlfn.T.DIST(SQRT(E8)*(H8-G8)/SQRT('2.0'!U8),E8-1,TRUE)),"") | AJ8: =IFERROR(IF(COUNTA(E8:W8)=0,"",IF(ABS('2.0'!W8-AI8)>0.00001,"NOT OK","OK")),"") | AR8: N | AS8: =SUM($I$10:$T$21) -> 25000 | AU8: N | AV8: i/j
AR9: w_r | AS9: {=POWER($AS$8,2)-SUMPRODUCT(AU10:AU21,AU10:AU21)} -> 560856534 | AW9: 1 | AX9: 2 | AY9: 3 | AZ9: 4 | BA9: 5 | BB9: 6 | BC9: 7 | BD9: 8 | BE9: 9 | BF9: 10 | BG9: 11 | BH9: 12
B10: 201 | C10: Segment 1 | D10: [0%,5%) | I10: 1406 | J10: 130 | K10: 14 | L10: 2 | M10: 20 | N10: 1 | O10: 1 | P10: 0 | Q10: 3 | R10: 57 | S10: 0 | T10: 0 | Y10: =IF(COUNTA(E10:W10)=0,"",IF(AND('2.0'!E10=0,COUNTA(H10:W10)>0),"NOT OK",IF(OR(AA10="NOT OK",AB10="NOT OK",AJ10="NOT OK"),"NOT OK",IF(AND(OR(AE10="WARNING",AH10="WARNING"),E10>0),"WARNING","OK")))) -> NOT OK | Z10: =IF(OR(COUNTA(E10:W10)=0,AND('2.0'!E10=0,COUNTA(F10:W10)=0)),"",IF(AND(E10=0,COUNTA(H10:W10)>0),"As number of facilities is zero, please leave columns H to W empty.",IF(AA10="NOT OK","Row incomplete. Check if zeros values are missing in the row.",IF(AB10="NOT OK","The number of facilities in buckets does not sum up to the total number.",IF(AJ10="NOT OK","The p-value of t-Test differs from ECB calculation.",IF(AE10="WARNING","The average LGD^R seems implausible with the given LGD realisation.",IF(AH10="WARNING","The variance of the LGD seems implausible with the given realisation.",""))))))) -> As number of facilities is zero, please leave columns H to W empty. | AA10: =IF(OR(E10=0,COUNTA(E10:W10)=0),"",IF(COUNTA(E10:W10)>=18,"OK",IF('2.0'!E10=1,IF(COUNTA(E10:W10)=15,"OK","NOT OK"),"NOT OK"))) | AB10: =IF(COUNTA(E10:W10)=0,"",IF('2.0'!E10=SUM(I10:T10),"OK","NOT OK")) -> NOT OK | AC10: {=IFERROR(SUM(I10:T10*TRANSPOSE($AK$10:$AK$21))/SUM(I10:T10),"")} -> 0.038494492 | AD10: {=IFERROR(SUM(I10:T10*TRANSPOSE($AL$10:$AL$21))/SUM(I10:T10),"")} -> 0.091493268 | AE10: =IF(COUNTA(H10:W10)=0,"",IFERROR(IF(AND('2.0'!H10>=AC10,H10<=AD10),"OK","WARNING"),"")) -> WARNING | AF10: =IF(COUNTA(H10:W10)=0,"",IFERROR('2.0'!AP31,"")) -> 0.024926516 | AG10: =IF(COUNTA(H10:W10)=0,"",IFERROR('2.0'!AO31,"")) -> 0.035183711 | AH10: =IF(COUNTA(H10:W10)=0,"",IFERROR(IF(AND('2.0'!U10>=AF10,U10<=AG10),"OK","WARNING"),"")) -> WARNING | AI10: =IFERROR(IF(COUNTA(E10:W10)=0,"",1-_xlfn.T.DIST(SQRT(E10)*(H10-G10)/SQRT('2.0'!U10),E10-1,TRUE)),"") | AJ10: =IFERROR(IF(COUNTA(E10:W10)=0,"",IF(ABS('2.0'!W10-AI10)>0.00001,"NOT OK","OK")),"") | AK10: 0 | AL10: 0.05 | AM10: 0.025 | AR10: P-Q | AS10: {=SUM((AW10:BH21)*$I$10:$T$21)} -> 195471380 | AU10: =SUM(I10:T10) -> 1634 | AV10: 1 | AW10: {=(SUM(($AW$9:$BH$9<AW$9)*($AV$10:$AV$21<$AV10)*$I$10:$T$21)+SUM(($AW$9:$BH$9>AW$9)*($AV$10:$AV$21>$AV10)*$I$10:$T$21)-(SUM(($AW$9:$BH$9>AW$9)*($AV$10:$AV$21<$AV10)*$I$10:$T$21)+SUM(($AW$9:$BH$9<AW$9)*($AV$10:$AV$21>$AV10)*$I$10:$T$21)))*($AU10>0)*(SUM(INDEX($I$10:$T$21,0,AW$9))>0)} -> 19272 | AX10: {=(SUM(($AW$9:$BH$9<AX$9)*($AV$10:$AV$21<$AV10)*$I$10:$T$21)+SUM(($AW$9:$BH$9>AX$9)*($AV$10:$AV$21>$AV10)*$I$10:$T$21)-(SUM(($AW$9:$BH$9>AX$9)*($AV$10:$AV$21<$AV10)*$I$10:$T$21)+SUM(($AW$9:$BH$9<AX$9)*($AV$10:$AV$21>$AV10)*$I$10:$T$21)))*($AU10>0)*(SUM(INDEX($I$10:$T$21,0,AX$9))>0)} -> 13708 | AY10: {=(SUM(($AW$9:$BH$9<AY$9)*($AV$10:$AV$21<$AV10)*$I$10:$T$21)+SUM(($AW$9:$BH$9>AY$9)*($AV$10:$AV$21>$AV10)*$I$10:$T$21)-(SUM(($AW$9:$BH$9>AY$9)*($AV$10:$AV$21<$AV10)*$I$10:$T$21)+SUM(($AW$9:$BH$9<AY$9)*($AV$10:$AV$21>$AV10)*$I$10:$T$21)))*($AU10>0)*(SUM(INDEX($I$10:$T$21,0,AY$9))>0)} -> 11582 | AZ10: {=(SUM(($AW$9:$BH$9<AZ$9)*($AV$10:$AV$21<$AV10)*$I$10:$T$21)+SUM(($AW$9:$BH$9>AZ$9)*($AV$10:$AV$21>$AV10)*$I$10:$T$21)-(SUM(($AW$9:$BH$9>AZ$9)*($AV$10:$AV$21<$AV10)*$I$10:$T$21)+SUM(($AW$9:$BH$9<AZ$9)*($AV$10:$AV$21>$AV10)*$I$10:$T$21)))*($AU10>0)*(SUM(INDEX($I$10:$T$21,0,AZ$9))>0)} -> 10678 | BA10: {=(SUM(($AW$9:$BH$9<BA$9)*($AV$10:$AV$21<$AV10)*$I$10:$T$21)+SUM(($AW$9:$BH$9>BA$9)*($AV$10:$AV$21>$AV10)*$I$10:$T$21)-(SUM(($AW$9:$BH$9>BA$9)*($AV$10:$AV$21<$AV10)*$I$10:$T$21)+SUM(($AW$9:$BH$9<BA$9)*($AV$10:$AV$21>$AV10)*$I$10:$T$21)))*($AU10>0)*(SUM(INDEX($I$10:$T$21,0,BA$9))>0)} -> 10090 | BB10: {=(SUM(($AW$9:$BH$9<BB$9)*($AV$10:$AV$21<$AV10)*$I$10:$T$21)+SUM(($AW$9:$BH$9>BB$9)*($AV$10:$AV$21>$AV10)*$I$10:$T$21)-(SUM(($AW$9:$BH$9>BB$9)*($AV$10:$AV$21<$AV10)*$I$10:$T$21)+SUM(($AW$9:$BH$9<BB$9)*($AV$10:$AV$21>$AV10)*$I$10:$T$21)))*($AU10>0)*(SUM(INDEX($I$10:$T$21,0,BB$9))>0)} -> 9731 | BC10: {=(SUM(($AW$9:$BH$9<BC$9)*($AV$10:$AV$21<$AV10)*$I$10:$T$21)+SUM(($AW$9:$BH$9>BC$9)*($AV$10:$AV$21>$AV10)*$I$10:$T$21)-(SUM(($AW$9:$BH$9>BC$9)*($AV$10:$AV$21<$AV10)*$I$10:$T$21)+SUM(($AW$9:$BH$9<BC$9)*($AV$10:$AV$21>$AV10)*$I$10:$T$21)))*($AU10>0)*(SUM(INDEX($I$10:$T$21,0,BC$9))>0)} -> 9668 | BD10: {=(SUM(($AW$9:$BH$9<BD$9)*($AV$10:$AV$21<$AV10)*$I$10:$T$21)+SUM(($AW$9:$BH$9>BD$9)*($AV$10:$AV$21>$AV10)*$I$10:$T$21)-(SUM(($AW$9:$BH$9>BD$9)*($AV$10:$AV$21<$AV10)*$I$10:$T$21)+SUM(($AW$9:$BH$9<BD$9)*($AV$10:$AV$21>$AV10)*$I$10:$T$21)))*($AU10>0)*(SUM(INDEX($I$10:$T$21,0,BD$9))>0)} -> 9549 | ... BH10: {=(SUM(($AW$9:$BH$9<BH$9)*($AV$10:$AV$21<$AV10)*$I$10:$T$21)+SUM(($AW$9:$BH$9>BH$9)*($AV$10:$AV$21>$AV10)*$I$10:$T$21)-(SUM(($AW$9:$BH$9>BH$9)*($AV$10:$AV$21<$AV10)*$I$10:$T$21)+SUM(($AW$9:$BH$9<BH$9)*($AV$10:$AV$21>$AV10)*$I$10:$T$21)))*($AU10>0)*(SUM(INDEX($I$10:$T$21,0,BH$9))>0)} -> -21366
B11: 202 | C11: Segment 2 | D11: [5%,10%) | I11: 584 | J11: 300 | K11: 320 | L11: 43 | M11: 8 | N11: 0 | O11: 0 | P11: 0 | Q11: 0 | R11: 0 | S11: 240 | T11: 0 | Y11: =IF(COUNTA(E11:W11)=0,"",IF(AND('2.0'!E11=0,COUNTA(H11:W11)>0),"NOT OK",IF(OR(AA11="NOT OK",AB11="NOT OK",AJ11="NOT OK"),"NOT OK",IF(AND(OR(AE11="WARNING",AH11="WARNING"),E11>0),"WARNING","OK")))) -> NOT OK | Z11: =IF(OR(COUNTA(E11:W11)=0,AND('2.0'!E11=0,COUNTA(F11:W11)=0)),"",IF(AND(E11=0,COUNTA(H11:W11)>0),"As number of facilities is zero, please leave columns H to W empty.",IF(AA11="NOT OK","Row incomplete. Check if zeros values are missing in the row.",IF(AB11="NOT OK","The number of facilities in buckets does not sum up to the total number.",IF(AJ11="NOT OK","The p-value of t-Test differs from ECB calculation.",IF(AE11="WARNING","The average LGD^R seems implausible with the given LGD realisation.",IF(AH11="WARNING","The variance of the LGD seems implausible with the given realisation.",""))))))) -> As number of facilities is zero, please leave columns H to W empty. | AA11: =IF(OR(E11=0,COUNTA(E11:W11)=0),"",IF(COUNTA(E11:W11)>=18,"OK",IF('2.0'!E11=1,IF(COUNTA(E11:W11)=15,"OK","NOT OK"),"NOT OK"))) | AB11: =IF(COUNTA(E11:W11)=0,"",IF('2.0'!E11=SUM(I11:T11),"OK","NOT OK")) -> NOT OK | AC11: {=IFERROR(SUM(I11:T11*TRANSPOSE($AK$10:$AK$21))/SUM(I11:T11),"")} -> 0.18327759 | AD11: {=IFERROR(SUM(I11:T11*TRANSPOSE($AL$10:$AL$21))/SUM(I11:T11),"")} -> 0.25371237 | AE11: =IF(COUNTA(H11:W11)=0,"",IFERROR(IF(AND('2.0'!H11>=AC11,H11<=AD11),"OK","WARNING"),"")) -> WARNING | AF11: =IF(COUNTA(H11:W11)=0,"",IFERROR('2.0'!AP32,"")) -> 0.13439759 | AG11: =IF(COUNTA(H11:W11)=0,"",IFERROR('2.0'!AO32,"")) -> 0.17564257 | AH11: =IF(COUNTA(H11:W11)=0,"",IFERROR(IF(AND('2.0'!U11>=AF11,U11<=AG11),"OK","WARNING"),"")) -> WARNING | AI11: =IFERROR(IF(COUNTA(E11:W11)=0,"",1-_xlfn.T.DIST(SQRT(E11)*(H11-G11)/SQRT('2.0'!U11),E11-1,TRUE)),"") | AJ11: =IFERROR(IF(COUNTA(E11:W11)=0,"",IF(ABS('2.0'!W11-AI11)>0.00001,"NOT OK","OK")),"") | AK11: 0.05 | AL11: 0.1 | AM11: 0.075 | AR11: D(C|R) | AS11: =AS10/AS9 -> 0.34852296 | AU11: =SUM(I11:T11) -> 1495 | AV11: 2 | AW11: {=(SUM(($AW$9:$BH$9<AW$9)*($AV$10:$AV$21<$AV11)*$I$10:$T$21)+SUM(($AW$9:$BH$9>AW$9)*($AV$10:$AV$21>$AV11)*$I$10:$T$21)-(SUM(($AW$9:$BH$9>AW$9)*($AV$10:$AV$21<$AV11)*$I$10:$T$21)+SUM(($AW$9:$BH$9<AW$9)*($AV$10:$AV$21>$AV11)*$I$10:$T$21)))*($AU11>0)*(SUM(INDEX($I$10:$T$21,0,AW$9))>0)} -> 18133 | AX11: {=(SUM(($AW$9:$BH$9<AX$9)*($AV$10:$AV$21<$AV11)*$I$10:$T$21)+SUM(($AW$9:$BH$9>AX$9)*($AV$10:$AV$21>$AV11)*$I$10:$T$21)-(SUM(($AW$9:$BH$9>AX$9)*($AV$10:$AV$21<$AV11)*$I$10:$T$21)+SUM(($AW$9:$BH$9<AX$9)*($AV$10:$AV$21>$AV11)*$I$10:$T$21)))*($AU11>0)*(SUM(INDEX($I$10:$T$21,0,AX$9))>0)} -> 14989 | AY11: {=(SUM(($AW$9:$BH$9<AY$9)*($AV$10:$AV$21<$AV11)*$I$10:$T$21)+SUM(($AW$9:$BH$9>AY$9)*($AV$10:$AV$21>$AV11)*$I$10:$T$21)-(SUM(($AW$9:$BH$9>AY$9)*($AV$10:$AV$21<$AV11)*$I$10:$T$21)+SUM(($AW$9:$BH$9<AY$9)*($AV$10:$AV$21>$AV11)*$I$10:$T$21)))*($AU11>0)*(SUM(INDEX($I$10:$T$21,0,AY$9))>0)} -> 13627 | AZ11: {=(SUM(($AW$9:$BH$9<AZ$9)*($AV$10:$AV$21<$AV11)*$I$10:$T$21)+SUM(($AW$9:$BH$9>AZ$9)*($AV$10:$AV$21>$AV11)*$I$10:$T$21)-(SUM(($AW$9:$BH$9>AZ$9)*($AV$10:$AV$21<$AV11)*$I$10:$T$21)+SUM(($AW$9:$BH$9<AZ$9)*($AV$10:$AV$21>$AV11)*$I$10:$T$21)))*($AU11>0)*(SUM(INDEX($I$10:$T$21,0,AZ$9))>0)} -> 13102 | BA11: {=(SUM(($AW$9:$BH$9<BA$9)*($AV$10:$AV$21<$AV11)*$I$10:$T$21)+SUM(($AW$9:$BH$9>BA$9)*($AV$10:$AV$21>$AV11)*$I$10:$T$21)-(SUM(($AW$9:$BH$9>BA$9)*($AV$10:$AV$21<$AV11)*$I$10:$T$21)+SUM(($AW$9:$BH$9<BA$9)*($AV$10:$AV$21>$AV11)*$I$10:$T$21)))*($AU11>0)*(SUM(INDEX($I$10:$T$21,0,BA$9))>0)} -> 12587 | BB11: {=(SUM(($AW$9:$BH$9<BB$9)*($AV$10:$AV$21<$AV11)*$I$10:$T$21)+SUM(($AW$9:$BH$9>BB$9)*($AV$10:$AV$21>$AV11)*$I$10:$T$21)-(SUM(($AW$9:$BH$9>BB$9)*($AV$10:$AV$21<$AV11)*$I$10:$T$21)+SUM(($AW$9:$BH$9<BB$9)*($AV$10:$AV$21>$AV11)*$I$10:$T$21)))*($AU11>0)*(SUM(INDEX($I$10:$T$21,0,BB$9))>0)} -> 12257 | BC11: {=(SUM(($AW$9:$BH$9<BC$9)*($AV$10:$AV$21<$AV11)*$I$10:$T$21)+SUM(($AW$9:$BH$9>BC$9)*($AV$10:$AV$21>$AV11)*$I$10:$T$21)-(SUM(($AW$9:$BH$9>BC$9)*($AV$10:$AV$21<$AV11)*$I$10:$T$21)+SUM(($AW$9:$BH$9<BC$9)*($AV$10:$AV$21>$AV11)*$I$10:$T$21)))*($AU11>0)*(SUM(INDEX($I$10:$T$21,0,BC$9))>0)} -> 12196 | BD11: {=(SUM(($AW$9:$BH$9<BD$9)*($AV$10:$AV$21<$AV11)*$I$10:$T$21)+SUM(($AW$9:$BH$9>BD$9)*($AV$10:$AV$21>$AV11)*$I$10:$T$21)-(SUM(($AW$9:$BH$9>BD$9)*($AV$10:$AV$21<$AV11)*$I$10:$T$21)+SUM(($AW$9:$BH$9<BD$9)*($AV$10:$AV$21>$AV11)*$I$10:$T$21)))*($AU11>0)*(SUM(INDEX($I$10:$T$21,0,BD$9))>0)} -> 12078 | ... BH11: {=(SUM(($AW$9:$BH$9<BH$9)*($AV$10:$AV$21<$AV11)*$I$10:$T$21)+SUM(($AW$9:$BH$9>BH$9)*($AV$10:$AV$21>$AV11)*$I$10:$T$21)-(SUM(($AW$9:$BH$9>BH$9)*($AV$10:$AV$21<$AV11)*$I$10:$T$21)+SUM(($AW$9:$BH$9<BH$9)*($AV$10:$AV$21>$AV11)*$I$10:$T$21)))*($AU11>0)*(SUM(INDEX($I$10:$T$21,0,BH$9))>0)} -> -18237
B12: 203 | C12: Segment 3 | D12: [10%,20%) | I12: 448 | J12: 500 | K12: 10 | L12: 6 | M12: 65 | N12: 0 | O12: 1 | P12: 0 | Q12: 1 | R12: 56 | S12: 354 | T12: 0 | Y12: =IF(COUNTA(E12:W12)=0,"",IF(AND('2.0'!E12=0,COUNTA(H12:W12)>0),"NOT OK",IF(OR(AA12="NOT OK",AB12="NOT OK",AJ12="NOT OK"),"NOT OK",IF(AND(OR(AE12="WARNING",AH12="WARNING"),E12>0),"WARNING","OK")))) -> NOT OK | Z12: =IF(OR(COUNTA(E12:W12)=0,AND('2.0'!E12=0,COUNTA(F12:W12)=0)),"",IF(AND(E12=0,COUNTA(H12:W12)>0),"As number of facilities is zero, please leave columns H to W empty.",IF(AA12="NOT OK","Row incomplete. Check if zeros values are missing in the row.",IF(AB12="NOT OK","The number of facilities in buckets does not sum up to the total number.",IF(AJ12="NOT OK","The p-value of t-Test differs from ECB calculation.",IF(AE12="WARNING","The average LGD^R seems implausible with the given LGD realisation.",IF(AH12="WARNING","The variance of the LGD seems implausible with the given realisation.",""))))))) -> As number of facilities is zero, please leave columns H to W empty. | AA12: =IF(OR(E12=0,COUNTA(E12:W12)=0),"",IF(COUNTA(E12:W12)>=18,"OK",IF('2.0'!E12=1,IF(COUNTA(E12:W12)=15,"OK","NOT OK"),"NOT OK"))) | AB12: =IF(COUNTA(E12:W12)=0,"",IF('2.0'!E12=SUM(I12:T12),"OK","NOT OK")) -> NOT OK | AC12: {=IFERROR(SUM(I12:T12*TRANSPOSE($AK$10:$AK$21))/SUM(I12:T12),"")} -> 0.28542679 | AD12: {=IFERROR(SUM(I12:T12*TRANSPOSE($AL$10:$AL$21))/SUM(I12:T12),"")} -> 0.35253296 | AE12: =IF(COUNTA(H12:W12)=0,"",IFERROR(IF(AND('2.0'!H12>=AC12,H12<=AD12),"OK","WARNING"),"")) -> WARNING | AF12: =IF(COUNTA(H12:W12)=0,"",IFERROR('2.0'!AP33,"")) -> 0.22969444 | AG12: =IF(COUNTA(H12:W12)=0,"",IFERROR('2.0'!AO33,"")) -> 0.29015278 | AH12: =IF(COUNTA(H12:W12)=0,"",IFERROR(IF(AND('2.0'!U12>=AF12,U12<=AG12),"OK","WARNING"),"")) -> WARNING | AI12: =IFERROR(IF(COUNTA(E12:W12)=0,"",1-_xlfn.T.DIST(SQRT(E12)*(H12-G12)/SQRT('2.0'!U12),E12-1,TRUE)),"") | AJ12: =IFERROR(IF(COUNTA(E12:W12)=0,"",IF(ABS('2.0'!W12-AI12)>0.00001,"NOT OK","OK")),"") | AK12: 0.1 | AL12: 0.2 | AM12: 0.15 | AR12: gAUC | AS12: {=(AS11+1)/2} -> 0.67426148 | AU12: =SUM(I12:T12) -> 1441 | AV12: 3 | AW12: {=(SUM(($AW$9:$BH$9<AW$9)*($AV$10:$AV$21<$AV12)*$I$10:$T$21)+SUM(($AW$9:$BH$9>AW$9)*($AV$10:$AV$21>$AV12)*$I$10:$T$21)-(SUM(($AW$9:$BH$9>AW$9)*($AV$10:$AV$21<$AV12)*$I$10:$T$21)+SUM(($AW$9:$BH$9<AW$9)*($AV$10:$AV$21>$AV12)*$I$10:$T$21)))*($AU12>0)*(SUM(INDEX($I$10:$T$21,0,AW$9))>0)} -> 16229 | AX12: {=(SUM(($AW$9:$BH$9<AX$9)*($AV$10:$AV$21<$AV12)*$I$10:$T$21)+SUM(($AW$9:$BH$9>AX$9)*($AV$10:$AV$21>$AV12)*$I$10:$T$21)-(SUM(($AW$9:$BH$9>AX$9)*($AV$10:$AV$21<$AV12)*$I$10:$T$21)+SUM(($AW$9:$BH$9<AX$9)*($AV$10:$AV$21>$AV12)*$I$10:$T$21)))*($AU12>0)*(SUM(INDEX($I$10:$T$21,0,AX$9))>0)} -> 14917 | AY12: {=(SUM(($AW$9:$BH$9<AY$9)*($AV$10:$AV$21<$AV12)*$I$10:$T$21)+SUM(($AW$9:$BH$9>AY$9)*($AV$10:$AV$21>$AV12)*$I$10:$T$21)-(SUM(($AW$9:$BH$9>AY$9)*($AV$10:$AV$21<$AV12)*$I$10:$T$21)+SUM(($AW$9:$BH$9<AY$9)*($AV$10:$AV$21>$AV12)*$I$10:$T$21)))*($AU12>0)*(SUM(INDEX($I$10:$T$21,0,AY$9))>0)} -> 14685 | AZ12: {=(SUM(($AW$9:$BH$9<AZ$9)*($AV$10:$AV$21<$AV12)*$I$10:$T$21)+SUM(($AW$9:$BH$9>AZ$9)*($AV$10:$AV$21>$AV12)*$I$10:$T$21)-(SUM(($AW$9:$BH$9>AZ$9)*($AV$10:$AV$21<$AV12)*$I$10:$T$21)+SUM(($AW$9:$BH$9<AZ$9)*($AV$10:$AV$21>$AV12)*$I$10:$T$21)))*($AU12>0)*(SUM(INDEX($I$10:$T$21,0,AZ$9))>0)} -> 14539 | BA12: {=(SUM(($AW$9:$BH$9<BA$9)*($AV$10:$AV$21<$AV12)*$I$10:$T$21)+SUM(($AW$9:$BH$9>BA$9)*($AV$10:$AV$21>$AV12)*$I$10:$T$21)-(SUM(($AW$9:$BH$9>BA$9)*($AV$10:$AV$21<$AV12)*$I$10:$T$21)+SUM(($AW$9:$BH$9<BA$9)*($AV$10:$AV$21>$AV12)*$I$10:$T$21)))*($AU12>0)*(SUM(INDEX($I$10:$T$21,0,BA$9))>0)} -> 14146 | BB12: {=(SUM(($AW$9:$BH$9<BB$9)*($AV$10:$AV$21<$AV12)*$I$10:$T$21)+SUM(($AW$9:$BH$9>BB$9)*($AV$10:$AV$21>$AV12)*$I$10:$T$21)-(SUM(($AW$9:$BH$9>BB$9)*($AV$10:$AV$21<$AV12)*$I$10:$T$21)+SUM(($AW$9:$BH$9<BB$9)*($AV$10:$AV$21>$AV12)*$I$10:$T$21)))*($AU12>0)*(SUM(INDEX($I$10:$T$21,0,BB$9))>0)} -> 13889 | BC12: {=(SUM(($AW$9:$BH$9<BC$9)*($AV$10:$AV$21<$AV12)*$I$10:$T$21)+SUM(($AW$9:$BH$9>BC$9)*($AV$10:$AV$21>$AV12)*$I$10:$T$21)-(SUM(($AW$9:$BH$9>BC$9)*($AV$10:$AV$21<$AV12)*$I$10:$T$21)+SUM(($AW$9:$BH$9<BC$9)*($AV$10:$AV$21>$AV12)*$I$10:$T$21)))*($AU12>0)*(SUM(INDEX($I$10:$T$21,0,BC$9))>0)} -> 13829 | BD12: {=(SUM(($AW$9:$BH$9<BD$9)*($AV$10:$AV$21<$AV12)*$I$10:$T$21)+SUM(($AW$9:$BH$9>BD$9)*($AV$10:$AV$21>$AV12)*$I$10:$T$21)-(SUM(($AW$9:$BH$9>BD$9)*($AV$10:$AV$21<$AV12)*$I$10:$T$21)+SUM(($AW$9:$BH$9<BD$9)*($AV$10:$AV$21>$AV12)*$I$10:$T$21)))*($AU12>0)*(SUM(INDEX($I$10:$T$21,0,BD$9))>0)} -> 13712 | ... BH12: {=(SUM(($AW$9:$BH$9<BH$9)*($AV$10:$AV$21<$AV12)*$I$10:$T$21)+SUM(($AW$9:$BH$9>BH$9)*($AV$10:$AV$21>$AV12)*$I$10:$T$21)-(SUM(($AW$9:$BH$9>BH$9)*($AV$10:$AV$21<$AV12)*$I$10:$T$21)+SUM(($AW$9:$BH$9<BH$9)*($AV$10:$AV$21>$AV12)*$I$10:$T$21)))*($AU12>0)*(SUM(INDEX($I$10:$T$21,0,BH$9))>0)} -> -15301
B13: 204 | C13: Segment 4 | D13: [20%,30%) | I13: 1530 | J13: 50 | K13: 140 | L13: 70 | M13: 45 | N13: 0 | O13: 5 | P13: 9 | Q13: 20 | R13: 0 | S13: 9 | T13: 0 | Y13: =IF(COUNTA(E13:W13)=0,"",IF(AND('2.0'!E13=0,COUNTA(H13:W13)>0),"NOT OK",IF(OR(AA13="NOT OK",AB13="NOT OK",AJ13="NOT OK"),"NOT OK",IF(AND(OR(AE13="WARNING",AH13="WARNING"),E13>0),"WARNING","OK")))) -> NOT OK | Z13: =IF(OR(COUNTA(E13:W13)=0,AND('2.0'!E13=0,COUNTA(F13:W13)=0)),"",IF(AND(E13=0,COUNTA(H13:W13)>0),"As number of facilities is zero, please leave columns H to W empty.",IF(AA13="NOT OK","Row incomplete. Check if zeros values are missing in the row.",IF(AB13="NOT OK","The number of facilities in buckets does not sum up to the total number.",IF(AJ13="NOT OK","The p-value of t-Test differs from ECB calculation.",IF(AE13="WARNING","The average LGD^R seems implausible with the given LGD realisation.",IF(AH13="WARNING","The variance of the LGD seems implausible with the given realisation.",""))))))) -> As number of facilities is zero, please leave columns H to W empty. | AA13: =IF(OR(E13=0,COUNTA(E13:W13)=0),"",IF(COUNTA(E13:W13)>=18,"OK",IF('2.0'!E13=1,IF(COUNTA(E13:W13)=15,"OK","NOT OK"),"NOT OK"))) | AB13: =IF(COUNTA(E13:W13)=0,"",IF('2.0'!E13=SUM(I13:T13),"OK","NOT OK")) -> NOT OK | AC13: {=IFERROR(SUM(I13:T13*TRANSPOSE($AK$10:$AK$21))/SUM(I13:T13),"")} -> 0.039403621 | AD13: {=IFERROR(SUM(I13:T13*TRANSPOSE($AL$10:$AL$21))/SUM(I13:T13),"")} -> 0.097337593 | AE13: =IF(COUNTA(H13:W13)=0,"",IFERROR(IF(AND('2.0'!H13>=AC13,H13<=AD13),"OK","WARNING"),"")) -> WARNING | AF13: =IF(COUNTA(H13:W13)=0,"",IFERROR('2.0'!AP34,"")) -> 0.015958977 | AG13: =IF(COUNTA(H13:W13)=0,"",IFERROR('2.0'!AO34,"")) -> 0.02740277 | AH13: =IF(COUNTA(H13:W13)=0,"",IFERROR(IF(AND('2.0'!U13>=AF13,U13<=AG13),"OK","WARNING"),"")) -> WARNING | AI13: =IFERROR(IF(COUNTA(E13:W13)=0,"",1-_xlfn.T.DIST(SQRT(E13)*(H13-G13)/SQRT('2.0'!U13),E13-1,TRUE)),"") | AJ13: =IFERROR(IF(COUNTA(E13:W13)=0,"",IF(ABS('2.0'!W13-AI13)>0.00001,"NOT OK","OK")),"") | AK13: 0.2 | AL13: 0.3 | AM13: 0.25 | AR13: s | AS13: {=1/POWER($AS$9,2)*SQRT(SUM($I$10:$T$21*POWER($AS$9*AW10:BH21-$AS$10*($AS$8-$AU$10:$AU$21),2)))} -> 0.0021621099 | AU13: =SUM(I13:T13) -> 1878 | AV13: 4 | AW13: {=(SUM(($AW$9:$BH$9<AW$9)*($AV$10:$AV$21<$AV13)*$I$10:$T$21)+SUM(($AW$9:$BH$9>AW$9)*($AV$10:$AV$21>$AV13)*$I$10:$T$21)-(SUM(($AW$9:$BH$9>AW$9)*($AV$10:$AV$21<$AV13)*$I$10:$T$21)+SUM(($AW$9:$BH$9<AW$9)*($AV$10:$AV$21>$AV13)*$I$10:$T$21)))*($AU13>0)*(SUM(INDEX($I$10:$T$21,0,AW$9))>0)} -> 14888 | AX13: {=(SUM(($AW$9:$BH$9<AX$9)*($AV$10:$AV$21<$AV13)*$I$10:$T$21)+SUM(($AW$9:$BH$9>AX$9)*($AV$10:$AV$21>$AV13)*$I$10:$T$21)-(SUM(($AW$9:$BH$9>AX$9)*($AV$10:$AV$21<$AV13)*$I$10:$T$21)+SUM(($AW$9:$BH$9<AX$9)*($AV$10:$AV$21>$AV13)*$I$10:$T$21)))*($AU13>0)*(SUM(INDEX($I$10:$T$21,0,AX$9))>0)} -> 16104 | AY13: {=(SUM(($AW$9:$BH$9<AY$9)*($AV$10:$AV$21<$AV13)*$I$10:$T$21)+SUM(($AW$9:$BH$9>AY$9)*($AV$10:$AV$21>$AV13)*$I$10:$T$21)-(SUM(($AW$9:$BH$9>AY$9)*($AV$10:$AV$21<$AV13)*$I$10:$T$21)+SUM(($AW$9:$BH$9<AY$9)*($AV$10:$AV$21>$AV13)*$I$10:$T$21)))*($AU13>0)*(SUM(INDEX($I$10:$T$21,0,AY$9))>0)} -> 16572 | AZ13: {=(SUM(($AW$9:$BH$9<AZ$9)*($AV$10:$AV$21<$AV13)*$I$10:$T$21)+SUM(($AW$9:$BH$9>AZ$9)*($AV$10:$AV$21>$AV13)*$I$10:$T$21)-(SUM(($AW$9:$BH$9>AZ$9)*($AV$10:$AV$21<$AV13)*$I$10:$T$21)+SUM(($AW$9:$BH$9<AZ$9)*($AV$10:$AV$21>$AV13)*$I$10:$T$21)))*($AU13>0)*(SUM(INDEX($I$10:$T$21,0,AZ$9))>0)} -> 16652 | BA13: {=(SUM(($AW$9:$BH$9<BA$9)*($AV$10:$AV$21<$AV13)*$I$10:$T$21)+SUM(($AW$9:$BH$9>BA$9)*($AV$10:$AV$21>$AV13)*$I$10:$T$21)-(SUM(($AW$9:$BH$9>BA$9)*($AV$10:$AV$21<$AV13)*$I$10:$T$21)+SUM(($AW$9:$BH$9<BA$9)*($AV$10:$AV$21>$AV13)*$I$10:$T$21)))*($AU13>0)*(SUM(INDEX($I$10:$T$21,0,BA$9))>0)} -> 16445 | BB13: {=(SUM(($AW$9:$BH$9<BB$9)*($AV$10:$AV$21<$AV13)*$I$10:$T$21)+SUM(($AW$9:$BH$9>BB$9)*($AV$10:$AV$21>$AV13)*$I$10:$T$21)-(SUM(($AW$9:$BH$9>BB$9)*($AV$10:$AV$21<$AV13)*$I$10:$T$21)+SUM(($AW$9:$BH$9<BB$9)*($AV$10:$AV$21>$AV13)*$I$10:$T$21)))*($AU13>0)*(SUM(INDEX($I$10:$T$21,0,BB$9))>0)} -> 16298 | BC13: {=(SUM(($AW$9:$BH$9<BC$9)*($AV$10:$AV$21<$AV13)*$I$10:$T$21)+SUM(($AW$9:$BH$9>BC$9)*($AV$10:$AV$21>$AV13)*$I$10:$T$21)-(SUM(($AW$9:$BH$9>BC$9)*($AV$10:$AV$21<$AV13)*$I$10:$T$21)+SUM(($AW$9:$BH$9<BC$9)*($AV$10:$AV$21>$AV13)*$I$10:$T$21)))*($AU13>0)*(SUM(INDEX($I$10:$T$21,0,BC$9))>0)} -> 16244 | BD13: {=(SUM(($AW$9:$BH$9<BD$9)*($AV$10:$AV$21<$AV13)*$I$10:$T$21)+SUM(($AW$9:$BH$9>BD$9)*($AV$10:$AV$21>$AV13)*$I$10:$T$21)-(SUM(($AW$9:$BH$9>BD$9)*($AV$10:$AV$21<$AV13)*$I$10:$T$21)+SUM(($AW$9:$BH$9<BD$9)*($AV$10:$AV$21>$AV13)*$I$10:$T$21)))*($AU13>0)*(SUM(INDEX($I$10:$T$21,0,BD$9))>0)} -> 16142 | ... BH13: {=(SUM(($AW$9:$BH$9<BH$9)*($AV$10:$AV$21<$AV13)*$I$10:$T$21)+SUM(($AW$9:$BH$9>BH$9)*($AV$10:$AV$21>$AV13)*$I$10:$T$21)-(SUM(($AW$9:$BH$9>BH$9)*($AV$10:$AV$21<$AV13)*$I$10:$T$21)+SUM(($AW$9:$BH$9<BH$9)*($AV$10:$AV$21>$AV13)*$I$10:$T$21)))*($AU13>0)*(SUM(INDEX($I$10:$T$21,0,BH$9))>0)} -> -11982
B14: 205 | C14: Segment 5 | D14: [30%,40%) | I14: 200 | J14: 100 | K14: 10 | L14: 10 | M14: 80 | N14: 7 | O14: 3 | P14: 15 | Q14: 34 | R14: 5 | S14: 604 | T14: 0 | Y14: =IF(COUNTA(E14:W14)=0,"",IF(AND('2.0'!E14=0,COUNTA(H14:W14)>0),"NOT OK",IF(OR(AA14="NOT OK",AB14="NOT OK",AJ14="NOT OK"),"NOT OK",IF(AND(OR(AE14="WARNING",AH14="WARNING"),E14>0),"WARNING","OK")))) -> NOT OK | Z14: =IF(OR(COUNTA(E14:W14)=0,AND('2.0'!E14=0,COUNTA(F14:W14)=0)),"",IF(AND(E14=0,COUNTA(H14:W14)>0),"As number of facilities is zero, please leave columns H to W empty.",IF(AA14="NOT OK","Row incomplete. Check if zeros values are missing in the row.",IF(AB14="NOT OK","The number of facilities in buckets does not sum up to the total number.",IF(AJ14="NOT OK","The p-value of t-Test differs from ECB calculation.",IF(AE14="WARNING","The average LGD^R seems implausible with the given LGD realisation.",IF(AH14="WARNING","The variance of the LGD seems implausible with the given realisation.",""))))))) -> As number of facilities is zero, please leave columns H to W empty. | AA14: =IF(OR(E14=0,COUNTA(E14:W14)=0),"",IF(COUNTA(E14:W14)>=18,"OK",IF('2.0'!E14=1,IF(COUNTA(E14:W14)=15,"OK","NOT OK"),"NOT OK"))) | AB14: =IF(COUNTA(E14:W14)=0,"",IF('2.0'!E14=SUM(I14:T14),"OK","NOT OK")) -> NOT OK | AC14: {=IFERROR(SUM(I14:T14*TRANSPOSE($AK$10:$AK$21))/SUM(I14:T14),"")} -> 0.57743446 | AD14: {=IFERROR(SUM(I14:T14*TRANSPOSE($AL$10:$AL$21))/SUM(I14:T14),"")} -> 0.66338951 | AE14: =IF(COUNTA(H14:W14)=0,"",IFERROR(IF(AND('2.0'!H14>=AC14,H14<=AD14),"OK","WARNING"),"")) -> WARNING | AF14: =IF(COUNTA(H14:W14)=0,"",IFERROR('2.0'!AP35,"")) -> 0.49139644 | AG14: =IF(COUNTA(H14:W14)=0,"",IFERROR('2.0'!AO35,"")) -> 0.61442362 | AH14: =IF(COUNTA(H14:W14)=0,"",IFERROR(IF(AND('2.0'!U14>=AF14,U14<=AG14),"OK","WARNING"),"")) -> WARNING | AI14: =IFERROR(IF(COUNTA(E14:W14)=0,"",1-_xlfn.T.DIST(SQRT(E14)*(H14-G14)/SQRT('2.0'!U14),E14-1,TRUE)),"") | AJ14: =IFERROR(IF(COUNTA(E14:W14)=0,"",IF(ABS('2.0'!W14-AI14)>0.00001,"NOT OK","OK")),"") | AK14: 0.3 | AL14: 0.4 | AM14: 0.35 | AU14: =SUM(I14:T14) -> 1068 | AV14: 5 | AW14: {=(SUM(($AW$9:$BH$9<AW$9)*($AV$10:$AV$21<$AV14)*$I$10:$T$21)+SUM(($AW$9:$BH$9>AW$9)*($AV$10:$AV$21>$AV14)*$I$10:$T$21)-(SUM(($AW$9:$BH$9>AW$9)*($AV$10:$AV$21<$AV14)*$I$10:$T$21)+SUM(($AW$9:$BH$9<AW$9)*($AV$10:$AV$21>$AV14)*$I$10:$T$21)))*($AU14>0)*(SUM(INDEX($I$10:$T$21,0,AW$9))>0)} -> 13672 | AX14: {=(SUM(($AW$9:$BH$9<AX$9)*($AV$10:$AV$21<$AV14)*$I$10:$T$21)+SUM(($AW$9:$BH$9>AX$9)*($AV$10:$AV$21>$AV14)*$I$10:$T$21)-(SUM(($AW$9:$BH$9>AX$9)*($AV$10:$AV$21<$AV14)*$I$10:$T$21)+SUM(($AW$9:$BH$9<AX$9)*($AV$10:$AV$21>$AV14)*$I$10:$T$21)))*($AU14>0)*(SUM(INDEX($I$10:$T$21,0,AX$9))>0)} -> 16768 | AY14: {=(SUM(($AW$9:$BH$9<AY$9)*($AV$10:$AV$21<$AV14)*$I$10:$T$21)+SUM(($AW$9:$BH$9>AY$9)*($AV$10:$AV$21>$AV14)*$I$10:$T$21)-(SUM(($AW$9:$BH$9>AY$9)*($AV$10:$AV$21<$AV14)*$I$10:$T$21)+SUM(($AW$9:$BH$9<AY$9)*($AV$10:$AV$21>$AV14)*$I$10:$T$21)))*($AU14>0)*(SUM(INDEX($I$10:$T$21,0,AY$9))>0)} -> 17536 | AZ14: {=(SUM(($AW$9:$BH$9<AZ$9)*($AV$10:$AV$21<$AV14)*$I$10:$T$21)+SUM(($AW$9:$BH$9>AZ$9)*($AV$10:$AV$21>$AV14)*$I$10:$T$21)-(SUM(($AW$9:$BH$9>AZ$9)*($AV$10:$AV$21<$AV14)*$I$10:$T$21)+SUM(($AW$9:$BH$9<AZ$9)*($AV$10:$AV$21>$AV14)*$I$10:$T$21)))*($AU14>0)*(SUM(INDEX($I$10:$T$21,0,AZ$9))>0)} -> 17846 | BA14: {=(SUM(($AW$9:$BH$9<BA$9)*($AV$10:$AV$21<$AV14)*$I$10:$T$21)+SUM(($AW$9:$BH$9>BA$9)*($AV$10:$AV$21>$AV14)*$I$10:$T$21)-(SUM(($AW$9:$BH$9>BA$9)*($AV$10:$AV$21<$AV14)*$I$10:$T$21)+SUM(($AW$9:$BH$9<BA$9)*($AV$10:$AV$21>$AV14)*$I$10:$T$21)))*($AU14>0)*(SUM(INDEX($I$10:$T$21,0,BA$9))>0)} -> 17844 | BB14: {=(SUM(($AW$9:$BH$9<BB$9)*($AV$10:$AV$21<$AV14)*$I$10:$T$21)+SUM(($AW$9:$BH$9>BB$9)*($AV$10:$AV$21>$AV14)*$I$10:$T$21)-(SUM(($AW$9:$BH$9>BB$9)*($AV$10:$AV$21<$AV14)*$I$10:$T$21)+SUM(($AW$9:$BH$9<BB$9)*($AV$10:$AV$21>$AV14)*$I$10:$T$21)))*($AU14>0)*(SUM(INDEX($I$10:$T$21,0,BB$9))>0)} -> 17829 | BC14: {=(SUM(($AW$9:$BH$9<BC$9)*($AV$10:$AV$21<$AV14)*$I$10:$T$21)+SUM(($AW$9:$BH$9>BC$9)*($AV$10:$AV$21>$AV14)*$I$10:$T$21)-(SUM(($AW$9:$BH$9>BC$9)*($AV$10:$AV$21<$AV14)*$I$10:$T$21)+SUM(($AW$9:$BH$9<BC$9)*($AV$10:$AV$21>$AV14)*$I$10:$T$21)))*($AU14>0)*(SUM(INDEX($I$10:$T$21,0,BC$9))>0)} -> 17790 | BD14: {=(SUM(($AW$9:$BH$9<BD$9)*($AV$10:$AV$21<$AV14)*$I$10:$T$21)+SUM(($AW$9:$BH$9>BD$9)*($AV$10:$AV$21>$AV14)*$I$10:$T$21)-(SUM(($AW$9:$BH$9>BD$9)*($AV$10:$AV$21<$AV14)*$I$10:$T$21)+SUM(($AW$9:$BH$9<BD$9)*($AV$10:$AV$21>$AV14)*$I$10:$T$21)))*($AU14>0)*(SUM(INDEX($I$10:$T$21,0,BD$9))>0)} -> 17720 | ... BH14: {=(SUM(($AW$9:$BH$9<BH$9)*($AV$10:$AV$21<$AV14)*$I$10:$T$21)+SUM(($AW$9:$BH$9>BH$9)*($AV$10:$AV$21>$AV14)*$I$10:$T$21)-(SUM(($AW$9:$BH$9>BH$9)*($AV$10:$AV$21<$AV14)*$I$10:$T$21)+SUM(($AW$9:$BH$9<BH$9)*($AV$10:$AV$21>$AV14)*$I$10:$T$21)))*($AU14>0)*(SUM(INDEX($I$10:$T$21,0,BH$9))>0)} -> -9036
B15: 206 | C15: Segment 6 | D15: [40%,50%) | I15: 584 | J15: 120 | K15: 104 | L15: 50 | M15: 40 | N15: 1 | O15: 7 | P15: 2 | Q15: 87 | R15: 67 | S15: 364 | T15: 0 | Y15: =IF(COUNTA(E15:W15)=0,"",IF(AND('2.0'!E15=0,COUNTA(H15:W15)>0),"NOT OK",IF(OR(AA15="NOT OK",AB15="NOT OK",AJ15="NOT OK"),"NOT OK",IF(AND(OR(AE15="WARNING",AH15="WARNING"),E15>0),"WARNING","OK")))) -> NOT OK | Z15: =IF(OR(COUNTA(E15:W15)=0,AND('2.0'!E15=0,COUNTA(F15:W15)=0)),"",IF(AND(E15=0,COUNTA(H15:W15)>0),"As number of facilities is zero, please leave columns H to W empty.",IF(AA15="NOT OK","Row incomplete. Check if zeros values are missing in the row.",IF(AB15="NOT OK","The number of facilities in buckets does not sum up to the total number.",IF(AJ15="NOT OK","The p-value of t-Test differs from ECB calculation.",IF(AE15="WARNING","The average LGD^R seems implausible with the given LGD realisation.",IF(AH15="WARNING","The variance of the LGD seems implausible with the given realisation.",""))))))) -> As number of facilities is zero, please leave columns H to W empty. | AA15: =IF(OR(E15=0,COUNTA(E15:W15)=0),"",IF(COUNTA(E15:W15)>=18,"OK",IF('2.0'!E15=1,IF(COUNTA(E15:W15)=15,"OK","NOT OK"),"NOT OK"))) | AB15: =IF(COUNTA(E15:W15)=0,"",IF('2.0'!E15=SUM(I15:T15),"OK","NOT OK")) -> NOT OK | AC15: {=IFERROR(SUM(I15:T15*TRANSPOSE($AK$10:$AK$21))/SUM(I15:T15),"")} -> 0.34053296 | AD15: {=IFERROR(SUM(I15:T15*TRANSPOSE($AL$10:$AL$21))/SUM(I15:T15),"")} -> 0.41584853 | AE15: =IF(COUNTA(H15:W15)=0,"",IFERROR(IF(AND('2.0'!H15>=AC15,H15<=AD15),"OK","WARNING"),"")) -> WARNING | AF15: =IF(COUNTA(H15:W15)=0,"",IFERROR('2.0'!AP36,"")) -> 0.27362807 | AG15: =IF(COUNTA(H15:W15)=0,"",IFERROR('2.0'!AO36,"")) -> 0.34766316 | AH15: =IF(COUNTA(H15:W15)=0,"",IFERROR(IF(AND('2.0'!U15>=AF15,U15<=AG15),"OK","WARNING"),"")) -> WARNING | AI15: =IFERROR(IF(COUNTA(E15:W15)=0,"",1-_xlfn.T.DIST(SQRT(E15)*(H15-G15)/SQRT('2.0'!U15),E15-1,TRUE)),"") | AJ15: =IFERROR(IF(COUNTA(E15:W15)=0,"",IF(ABS('2.0'!W15-AI15)>0.00001,"NOT OK","OK")),"") | AK15: 0.4 | AL15: 0.5 | AM15: 0.45 | AU15: =SUM(I15:T15) -> 1426 | AV15: 6 | AW15: {=(SUM(($AW$9:$BH$9<AW$9)*($AV$10:$AV$21<$AV15)*$I$10:$T$21)+SUM(($AW$9:$BH$9>AW$9)*($AV$10:$AV$21>$AV15)*$I$10:$T$21)-(SUM(($AW$9:$BH$9>AW$9)*($AV$10:$AV$21<$AV15)*$I$10:$T$21)+SUM(($AW$9:$BH$9<AW$9)*($AV$10:$AV$21>$AV15)*$I$10:$T$21)))*($AU15>0)*(SUM(INDEX($I$10:$T$21,0,AW$9))>0)} -> 11962 | AX15: {=(SUM(($AW$9:$BH$9<AX$9)*($AV$10:$AV$21<$AV15)*$I$10:$T$21)+SUM(($AW$9:$BH$9>AX$9)*($AV$10:$AV$21>$AV15)*$I$10:$T$21)-(SUM(($AW$9:$BH$9>AX$9)*($AV$10:$AV$21<$AV15)*$I$10:$T$21)+SUM(($AW$9:$BH$9<AX$9)*($AV$10:$AV$21>$AV15)*$I$10:$T$21)))*($AU15>0)*(SUM(INDEX($I$10:$T$21,0,AX$9))>0)} -> 16062 | AY15: {=(SUM(($AW$9:$BH$9<AY$9)*($AV$10:$AV$21<$AV15)*$I$10:$T$21)+SUM(($AW$9:$BH$9>AY$9)*($AV$10:$AV$21>$AV15)*$I$10:$T$21)-(SUM(($AW$9:$BH$9>AY$9)*($AV$10:$AV$21<$AV15)*$I$10:$T$21)+SUM(($AW$9:$BH$9<AY$9)*($AV$10:$AV$21>$AV15)*$I$10:$T$21)))*($AU15>0)*(SUM(INDEX($I$10:$T$21,0,AY$9))>0)} -> 17164 | AZ15: {=(SUM(($AW$9:$BH$9<AZ$9)*($AV$10:$AV$21<$AV15)*$I$10:$T$21)+SUM(($AW$9:$BH$9>AZ$9)*($AV$10:$AV$21>$AV15)*$I$10:$T$21)-(SUM(($AW$9:$BH$9>AZ$9)*($AV$10:$AV$21<$AV15)*$I$10:$T$21)+SUM(($AW$9:$BH$9<AZ$9)*($AV$10:$AV$21>$AV15)*$I$10:$T$21)))*($AU15>0)*(SUM(INDEX($I$10:$T$21,0,AZ$9))>0)} -> 17648 | BA15: {=(SUM(($AW$9:$BH$9<BA$9)*($AV$10:$AV$21<$AV15)*$I$10:$T$21)+SUM(($AW$9:$BH$9>BA$9)*($AV$10:$AV$21>$AV15)*$I$10:$T$21)-(SUM(($AW$9:$BH$9>BA$9)*($AV$10:$AV$21<$AV15)*$I$10:$T$21)+SUM(($AW$9:$BH$9<BA$9)*($AV$10:$AV$21>$AV15)*$I$10:$T$21)))*($AU15>0)*(SUM(INDEX($I$10:$T$21,0,BA$9))>0)} -> 17826 | BB15: {=(SUM(($AW$9:$BH$9<BB$9)*($AV$10:$AV$21<$AV15)*$I$10:$T$21)+SUM(($AW$9:$BH$9>BB$9)*($AV$10:$AV$21>$AV15)*$I$10:$T$21)-(SUM(($AW$9:$BH$9>BB$9)*($AV$10:$AV$21<$AV15)*$I$10:$T$21)+SUM(($AW$9:$BH$9<BB$9)*($AV$10:$AV$21>$AV15)*$I$10:$T$21)))*($AU15>0)*(SUM(INDEX($I$10:$T$21,0,BB$9))>0)} -> 17939 | BC15: {=(SUM(($AW$9:$BH$9<BC$9)*($AV$10:$AV$21<$AV15)*$I$10:$T$21)+SUM(($AW$9:$BH$9>BC$9)*($AV$10:$AV$21>$AV15)*$I$10:$T$21)-(SUM(($AW$9:$BH$9>BC$9)*($AV$10:$AV$21<$AV15)*$I$10:$T$21)+SUM(($AW$9:$BH$9<BC$9)*($AV$10:$AV$21>$AV15)*$I$10:$T$21)))*($AU15>0)*(SUM(INDEX($I$10:$T$21,0,BC$9))>0)} -> 17918 | BD15: {=(SUM(($AW$9:$BH$9<BD$9)*($AV$10:$AV$21<$AV15)*$I$10:$T$21)+SUM(($AW$9:$BH$9>BD$9)*($AV$10:$AV$21>$AV15)*$I$10:$T$21)-(SUM(($AW$9:$BH$9>BD$9)*($AV$10:$AV$21<$AV15)*$I$10:$T$21)+SUM(($AW$9:$BH$9<BD$9)*($AV$10:$AV$21>$AV15)*$I$10:$T$21)))*($AU15>0)*(SUM(INDEX($I$10:$T$21,0,BD$9))>0)} -> 17875 | ... BH15: {=(SUM(($AW$9:$BH$9<BH$9)*($AV$10:$AV$21<$AV15)*$I$10:$T$21)+SUM(($AW$9:$BH$9>BH$9)*($AV$10:$AV$21>$AV15)*$I$10:$T$21)-(SUM(($AW$9:$BH$9>BH$9)*($AV$10:$AV$21<$AV15)*$I$10:$T$21)+SUM(($AW$9:$BH$9<BH$9)*($AV$10:$AV$21>$AV15)*$I$10:$T$21)))*($AU15>0)*(SUM(INDEX($I$10:$T$21,0,BH$9))>0)} -> -6542
B16: 207 | C16: Segment 7 | D16: [50%,60%) | I16: 25 | J16: 30 | K16: 20 | L16: 19 | M16: 55 | N16: 7 | O16: 15 | P16: 20 | Q16: 35 | R16: 15 | S16: 699 | T16: 8 | Y16: =IF(COUNTA(E16:W16)=0,"",IF(AND('2.0'!E16=0,COUNTA(H16:W16)>0),"NOT OK",IF(OR(AA16="NOT OK",AB16="NOT OK",AJ16="NOT OK"),"NOT OK",IF(AND(OR(AE16="WARNING",AH16="WARNING"),E16>0),"WARNING","OK")))) -> NOT OK | Z16: =IF(OR(COUNTA(E16:W16)=0,AND('2.0'!E16=0,COUNTA(F16:W16)=0)),"",IF(AND(E16=0,COUNTA(H16:W16)>0),"As number of facilities is zero, please leave columns H to W empty.",IF(AA16="NOT OK","Row incomplete. Check if zeros values are missing in the row.",IF(AB16="NOT OK","The number of facilities in buckets does not sum up to the total number.",IF(AJ16="NOT OK","The p-value of t-Test differs from ECB calculation.",IF(AE16="WARNING","The average LGD^R seems implausible with the given LGD realisation.",IF(AH16="WARNING","The variance of the LGD seems implausible with the given realisation.",""))))))) -> As number of facilities is zero, please leave columns H to W empty. | AA16: =IF(OR(E16=0,COUNTA(E16:W16)=0),"",IF(COUNTA(E16:W16)>=18,"OK",IF('2.0'!E16=1,IF(COUNTA(E16:W16)=15,"OK","NOT OK"),"NOT OK"))) | AB16: =IF(COUNTA(E16:W16)=0,"",IF('2.0'!E16=SUM(I16:T16),"OK","NOT OK")) -> NOT OK | AC16: {=IFERROR(SUM(I16:T16*TRANSPOSE($AK$10:$AK$21))/SUM(I16:T16),"")} -> 0.75917722 | AD16: {=IFERROR(SUM(I16:T16*TRANSPOSE($AL$10:$AL$21))/SUM(I16:T16),"")} -> 0.87231013 | AE16: =IF(COUNTA(H16:W16)=0,"",IFERROR(IF(AND('2.0'!H16>=AC16,H16<=AD16),"OK","WARNING"),"")) -> WARNING | AF16: =IF(COUNTA(H16:W16)=0,"",IFERROR('2.0'!AP37,"")) -> 0.6536378 | AG16: =IF(COUNTA(H16:W16)=0,"",IFERROR('2.0'!AO37,"")) -> 0.88085797 | AH16: =IF(COUNTA(H16:W16)=0,"",IFERROR(IF(AND('2.0'!U16>=AF16,U16<=AG16),"OK","WARNING"),"")) -> WARNING | AI16: =IFERROR(IF(COUNTA(E16:W16)=0,"",1-_xlfn.T.DIST(SQRT(E16)*(H16-G16)/SQRT('2.0'!U16),E16-1,TRUE)),"") | AJ16: =IFERROR(IF(COUNTA(E16:W16)=0,"",IF(ABS('2.0'!W16-AI16)>0.00001,"NOT OK","OK")),"") | AK16: 0.5 | AL16: 0.6 | AM16: 0.55 | AU16: =SUM(I16:T16) -> 948 | AV16: 7 | AW16: {=(SUM(($AW$9:$BH$9<AW$9)*($AV$10:$AV$21<$AV16)*$I$10:$T$21)+SUM(($AW$9:$BH$9>AW$9)*($AV$10:$AV$21>$AV16)*$I$10:$T$21)-(SUM(($AW$9:$BH$9>AW$9)*($AV$10:$AV$21<$AV16)*$I$10:$T$21)+SUM(($AW$9:$BH$9<AW$9)*($AV$10:$AV$21>$AV16)*$I$10:$T$21)))*($AU16>0)*(SUM(INDEX($I$10:$T$21,0,AW$9))>0)} -> 10197 | AX16: {=(SUM(($AW$9:$BH$9<AX$9)*($AV$10:$AV$21<$AV16)*$I$10:$T$21)+SUM(($AW$9:$BH$9>AX$9)*($AV$10:$AV$21>$AV16)*$I$10:$T$21)-(SUM(($AW$9:$BH$9>AX$9)*($AV$10:$AV$21<$AV16)*$I$10:$T$21)+SUM(($AW$9:$BH$9<AX$9)*($AV$10:$AV$21>$AV16)*$I$10:$T$21)))*($AU16>0)*(SUM(INDEX($I$10:$T$21,0,AX$9))>0)} -> 15056 | AY16: {=(SUM(($AW$9:$BH$9<AY$9)*($AV$10:$AV$21<$AV16)*$I$10:$T$21)+SUM(($AW$9:$BH$9>AY$9)*($AV$10:$AV$21>$AV16)*$I$10:$T$21)-(SUM(($AW$9:$BH$9>AY$9)*($AV$10:$AV$21<$AV16)*$I$10:$T$21)+SUM(($AW$9:$BH$9<AY$9)*($AV$10:$AV$21>$AV16)*$I$10:$T$21)))*($AU16>0)*(SUM(INDEX($I$10:$T$21,0,AY$9))>0)} -> 16432 | AZ16: {=(SUM(($AW$9:$BH$9<AZ$9)*($AV$10:$AV$21<$AV16)*$I$10:$T$21)+SUM(($AW$9:$BH$9>AZ$9)*($AV$10:$AV$21>$AV16)*$I$10:$T$21)-(SUM(($AW$9:$BH$9>AZ$9)*($AV$10:$AV$21<$AV16)*$I$10:$T$21)+SUM(($AW$9:$BH$9<AZ$9)*($AV$10:$AV$21>$AV16)*$I$10:$T$21)))*($AU16>0)*(SUM(INDEX($I$10:$T$21,0,AZ$9))>0)} -> 17109 | BA16: {=(SUM(($AW$9:$BH$9<BA$9)*($AV$10:$AV$21<$AV16)*$I$10:$T$21)+SUM(($AW$9:$BH$9>BA$9)*($AV$10:$AV$21>$AV16)*$I$10:$T$21)-(SUM(($AW$9:$BH$9>BA$9)*($AV$10:$AV$21<$AV16)*$I$10:$T$21)+SUM(($AW$9:$BH$9<BA$9)*($AV$10:$AV$21>$AV16)*$I$10:$T$21)))*($AU16>0)*(SUM(INDEX($I$10:$T$21,0,BA$9))>0)} -> 17451 | BB16: {=(SUM(($AW$9:$BH$9<BB$9)*($AV$10:$AV$21<$AV16)*$I$10:$T$21)+SUM(($AW$9:$BH$9>BB$9)*($AV$10:$AV$21>$AV16)*$I$10:$T$21)-(SUM(($AW$9:$BH$9>BB$9)*($AV$10:$AV$21<$AV16)*$I$10:$T$21)+SUM(($AW$9:$BH$9<BB$9)*($AV$10:$AV$21>$AV16)*$I$10:$T$21)))*($AU16>0)*(SUM(INDEX($I$10:$T$21,0,BB$9))>0)} -> 17667 | BC16: {=(SUM(($AW$9:$BH$9<BC$9)*($AV$10:$AV$21<$AV16)*$I$10:$T$21)+SUM(($AW$9:$BH$9>BC$9)*($AV$10:$AV$21>$AV16)*$I$10:$T$21)-(SUM(($AW$9:$BH$9>BC$9)*($AV$10:$AV$21<$AV16)*$I$10:$T$21)+SUM(($AW$9:$BH$9<BC$9)*($AV$10:$AV$21>$AV16)*$I$10:$T$21)))*($AU16>0)*(SUM(INDEX($I$10:$T$21,0,BC$9))>0)} -> 17676 | BD16: {=(SUM(($AW$9:$BH$9<BD$9)*($AV$10:$AV$21<$AV16)*$I$10:$T$21)+SUM(($AW$9:$BH$9>BD$9)*($AV$10:$AV$21>$AV16)*$I$10:$T$21)-(SUM(($AW$9:$BH$9>BD$9)*($AV$10:$AV$21<$AV16)*$I$10:$T$21)+SUM(($AW$9:$BH$9<BD$9)*($AV$10:$AV$21>$AV16)*$I$10:$T$21)))*($AU16>0)*(SUM(INDEX($I$10:$T$21,0,BD$9))>0)} -> 17677 | ... BH16: {=(SUM(($AW$9:$BH$9<BH$9)*($AV$10:$AV$21<$AV16)*$I$10:$T$21)+SUM(($AW$9:$BH$9>BH$9)*($AV$10:$AV$21>$AV16)*$I$10:$T$21)-(SUM(($AW$9:$BH$9>BH$9)*($AV$10:$AV$21<$AV16)*$I$10:$T$21)+SUM(($AW$9:$BH$9<BH$9)*($AV$10:$AV$21>$AV16)*$I$10:$T$21)))*($AU16>0)*(SUM(INDEX($I$10:$T$21,0,BH$9))>0)} -> -4176
B17: 208 | C17: Segment 8 | D17: [60%,70%) | I17: 200 | J17: 0 | K17: 30 | L17: 8 | M17: 37 | N17: 3 | O17: 7 | P17: 5 | Q17: 80 | R17: 77 | S17: 1250 | T17: 32 | Y17: =IF(COUNTA(E17:W17)=0,"",IF(AND('2.0'!E17=0,COUNTA(H17:W17)>0),"NOT OK",IF(OR(AA17="NOT OK",AB17="NOT OK",AJ17="NOT OK"),"NOT OK",IF(AND(OR(AE17="WARNING",AH17="WARNING"),E17>0),"WARNING","OK")))) -> NOT OK | Z17: =IF(OR(COUNTA(E17:W17)=0,AND('2.0'!E17=0,COUNTA(F17:W17)=0)),"",IF(AND(E17=0,COUNTA(H17:W17)>0),"As number of facilities is zero, please leave columns H to W empty.",IF(AA17="NOT OK","Row incomplete. Check if zeros values are missing in the row.",IF(AB17="NOT OK","The number of facilities in buckets does not sum up to the total number.",IF(AJ17="NOT OK","The p-value of t-Test differs from ECB calculation.",IF(AE17="WARNING","The average LGD^R seems implausible with the given LGD realisation.",IF(AH17="WARNING","The variance of the LGD seems implausible with the given realisation.",""))))))) -> As number of facilities is zero, please leave columns H to W empty. | AA17: =IF(OR(E17=0,COUNTA(E17:W17)=0),"",IF(COUNTA(E17:W17)>=18,"OK",IF('2.0'!E17=1,IF(COUNTA(E17:W17)=15,"OK","NOT OK"),"NOT OK"))) | AB17: =IF(COUNTA(E17:W17)=0,"",IF('2.0'!E17=SUM(I17:T17),"OK","NOT OK")) -> NOT OK | AC17: {=IFERROR(SUM(I17:T17*TRANSPOSE($AK$10:$AK$21))/SUM(I17:T17),"")} -> 0.75072296 | AD17: {=IFERROR(SUM(I17:T17*TRANSPOSE($AL$10:$AL$21))/SUM(I17:T17),"")} -> 0.88010411 | AE17: =IF(COUNTA(H17:W17)=0,"",IFERROR(IF(AND('2.0'!H17>=AC17,H17<=AD17),"OK","WARNING"),"")) -> WARNING | AF17: =IF(COUNTA(H17:W17)=0,"",IFERROR('2.0'!AP38,"")) -> 0.66027778 | AG17: =IF(COUNTA(H17:W17)=0,"",IFERROR('2.0'!AO38,"")) -> 0.96390625 | AH17: =IF(COUNTA(H17:W17)=0,"",IFERROR(IF(AND('2.0'!U17>=AF17,U17<=AG17),"OK","WARNING"),"")) -> WARNING | AI17: =IFERROR(IF(COUNTA(E17:W17)=0,"",1-_xlfn.T.DIST(SQRT(E17)*(H17-G17)/SQRT('2.0'!U17),E17-1,TRUE)),"") | AJ17: =IFERROR(IF(COUNTA(E17:W17)=0,"",IF(ABS('2.0'!W17-AI17)>0.00001,"NOT OK","OK")),"") | AK17: 0.6 | AL17: 0.7 | AM17: 0.65 | AU17: =SUM(I17:T17) -> 1729 | AV17: 8 | AW17: {=(SUM(($AW$9:$BH$9<AW$9)*($AV$10:$AV$21<$AV17)*$I$10:$T$21)+SUM(($AW$9:$BH$9>AW$9)*($AV$10:$AV$21>$AV17)*$I$10:$T$21)-(SUM(($AW$9:$BH$9>AW$9)*($AV$10:$AV$21<$AV17)*$I$10:$T$21)+SUM(($AW$9:$BH$9<AW$9)*($AV$10:$AV$21>$AV17)*$I$10:$T$21)))*($AU17>0)*(SUM(INDEX($I$10:$T$21,0,AW$9))>0)} -> 7745 | AX17: {=(SUM(($AW$9:$BH$9<AX$9)*($AV$10:$AV$21<$AV17)*$I$10:$T$21)+SUM(($AW$9:$BH$9>AX$9)*($AV$10:$AV$21>$AV17)*$I$10:$T$21)-(SUM(($AW$9:$BH$9>AX$9)*($AV$10:$AV$21<$AV17)*$I$10:$T$21)+SUM(($AW$9:$BH$9<AX$9)*($AV$10:$AV$21>$AV17)*$I$10:$T$21)))*($AU17>0)*(SUM(INDEX($I$10:$T$21,0,AX$9))>0)} -> 12859 | AY17: {=(SUM(($AW$9:$BH$9<AY$9)*($AV$10:$AV$21<$AV17)*$I$10:$T$21)+SUM(($AW$9:$BH$9>AY$9)*($AV$10:$AV$21>$AV17)*$I$10:$T$21)-(SUM(($AW$9:$BH$9>AY$9)*($AV$10:$AV$21<$AV17)*$I$10:$T$21)+SUM(($AW$9:$BH$9<AY$9)*($AV$10:$AV$21>$AV17)*$I$10:$T$21)))*($AU17>0)*(SUM(INDEX($I$10:$T$21,0,AY$9))>0)} -> 14315 | AZ17: {=(SUM(($AW$9:$BH$9<AZ$9)*($AV$10:$AV$21<$AV17)*$I$10:$T$21)+SUM(($AW$9:$BH$9>AZ$9)*($AV$10:$AV$21>$AV17)*$I$10:$T$21)-(SUM(($AW$9:$BH$9>AZ$9)*($AV$10:$AV$21<$AV17)*$I$10:$T$21)+SUM(($AW$9:$BH$9<AZ$9)*($AV$10:$AV$21>$AV17)*$I$10:$T$21)))*($AU17>0)*(SUM(INDEX($I$10:$T$21,0,AZ$9))>0)} -> 15069 | BA17: {=(SUM(($AW$9:$BH$9<BA$9)*($AV$10:$AV$21<$AV17)*$I$10:$T$21)+SUM(($AW$9:$BH$9>BA$9)*($AV$10:$AV$21>$AV17)*$I$10:$T$21)-(SUM(($AW$9:$BH$9>BA$9)*($AV$10:$AV$21<$AV17)*$I$10:$T$21)+SUM(($AW$9:$BH$9<BA$9)*($AV$10:$AV$21>$AV17)*$I$10:$T$21)))*($AU17>0)*(SUM(INDEX($I$10:$T$21,0,BA$9))>0)} -> 15530 | BB17: {=(SUM(($AW$9:$BH$9<BB$9)*($AV$10:$AV$21<$AV17)*$I$10:$T$21)+SUM(($AW$9:$BH$9>BB$9)*($AV$10:$AV$21>$AV17)*$I$10:$T$21)-(SUM(($AW$9:$BH$9>BB$9)*($AV$10:$AV$21<$AV17)*$I$10:$T$21)+SUM(($AW$9:$BH$9<BB$9)*($AV$10:$AV$21>$AV17)*$I$10:$T$21)))*($AU17>0)*(SUM(INDEX($I$10:$T$21,0,BB$9))>0)} -> 15848 | BC17: {=(SUM(($AW$9:$BH$9<BC$9)*($AV$10:$AV$21<$AV17)*$I$10:$T$21)+SUM(($AW$9:$BH$9>BC$9)*($AV$10:$AV$21>$AV17)*$I$10:$T$21)-(SUM(($AW$9:$BH$9>BC$9)*($AV$10:$AV$21<$AV17)*$I$10:$T$21)+SUM(($AW$9:$BH$9<BC$9)*($AV$10:$AV$21>$AV17)*$I$10:$T$21)))*($AU17>0)*(SUM(INDEX($I$10:$T$21,0,BC$9))>0)} -> 15889 | BD17: {=(SUM(($AW$9:$BH$9<BD$9)*($AV$10:$AV$21<$AV17)*$I$10:$T$21)+SUM(($AW$9:$BH$9>BD$9)*($AV$10:$AV$21>$AV17)*$I$10:$T$21)-(SUM(($AW$9:$BH$9>BD$9)*($AV$10:$AV$21<$AV17)*$I$10:$T$21)+SUM(($AW$9:$BH$9<BD$9)*($AV$10:$AV$21>$AV17)*$I$10:$T$21)))*($AU17>0)*(SUM(INDEX($I$10:$T$21,0,BD$9))>0)} -> 15937 | ... BH17: {=(SUM(($AW$9:$BH$9<BH$9)*($AV$10:$AV$21<$AV17)*$I$10:$T$21)+SUM(($AW$9:$BH$9>BH$9)*($AV$10:$AV$21>$AV17)*$I$10:$T$21)-(SUM(($AW$9:$BH$9>BH$9)*($AV$10:$AV$21<$AV17)*$I$10:$T$21)+SUM(($AW$9:$BH$9<BH$9)*($AV$10:$AV$21>$AV17)*$I$10:$T$21)))*($AU17>0)*(SUM(INDEX($I$10:$T$21,0,BH$9))>0)} -> -1539
